<?xml version="1.0"?>
  
<robot name="MyCo-3-0.59" xmlns:xacro="http://wiki.ros.org/xacro">
  
  <xacro:arg name="use_real_hardware" default="true" />
  <xacro:arg name="use_fake_hardware" default="false" />
  
  <!-- Load TRANSMISSION file: -->
  <xacro:include filename="$(find myco_3_590mm_ros2_gazebo)/urdf/myco_3_590mm_transmission.xacro" />
  <!-- Load GAZEBO/ROS2_CONTROL file: -->
  <xacro:include filename="$(find myco_3_590mm_ros2_gazebo)/urdf/myco_3_590mm_gazebo.xacro" />
  
  <xacro:property name="PI" value="3.1415926535897931"/>
  
  <xacro:property name="density" value="3.09"/>
  <!-- <xacro:macro name="myco_3_590mm"> -->
    
    <!-- TRANSMISSION: -->
    <xacro:myco_3_590mm_transmission />
    <!-- GAZEBO - ROS2_CONTROL: -->
    <xacro:myco_3_590mm_gazebo  
    use_real_hardware="$(arg use_real_hardware)" 
    use_fake_hardware="$(arg use_fake_hardware)"/>
  
   <link name="world"/>
  
  <joint name="world_base" type="fixed">
    <origin
      xyz="0 0 0"
      rpy="0 0 -1.57080" />
    <parent
      link="world" />
    <child
      link="myco_base_link" />
  </joint>
  
  <link name="myco_base_link"/>
  
  <joint name="myco_base_joint" type="fixed">
    <origin
      xyz="0 0 0"
      rpy="0 0 ${PI/2}" />
    <parent
      link="myco_base_link" />
    <child
      link="myco_base" />
  </joint>
  
 <link
    name="myco_base">
    <inertial>
      <origin
        xyz="-0.00027695983850127 7.63096615894048E-06 0.0268778601548512"
        rpy="0 0 0" />
      <mass
        value="0.7245785482549" />
      <inertia
        ixx="0.000970150109671104"
        ixy="3.6255400122117E-08"
        ixz="-1.47235460346171E-05"
        iyy="0.000882560393454694"
        iyz="-5.96416764696243E-08"
        izz="0.00145842795825581" />
    </inertial>
    <visual>
      <origin
        xyz="0 0 0"
        rpy="0 0 0" />
      <geometry>
        <mesh
          filename="file://$(find myco_description)/meshes/MyCo-3-0.59/myco_base.STL" />
      </geometry>
      <material
        name="">
        <color
          rgba="0.792156862745098 0.819607843137255 0.929411764705882 1" />
      </material>
    </visual>
    <collision>
      <origin
        xyz="0 0 0"
        rpy="0 0 0" />
      <geometry>
        <mesh
          filename="file://$(find myco_description)/meshes/MyCo-3-0.59/myco_base.STL" />
      </geometry>
    </collision>
  </link>
  <link
    name="myco_link1">
    <inertial>
      <origin
        xyz="-8.91539579847577E-06 -0.00563249327792538 -0.0303126440472883"
        rpy="0 0 0" />
      <mass
        value="1.92522085347325" />
      <inertia
        ixx="0.00587219615466828"
        ixy="-7.37315625439862E-07"
        ixz="-2.79907745035039E-07"
        iyy="0.00517271060907105"
        iyz="0.0011236969138874"
        izz="0.00316959851533252" />
    </inertial>
    <visual>
      <origin
        xyz="0 0 0"
        rpy="0 0 0" />
      <geometry>
        <mesh
          filename="file://$(find myco_description)/meshes/MyCo-3-0.59/myco_link1.STL" />
      </geometry>
      <material
        name="">
        <color
          rgba="0.650980392156863 0.619607843137255 0.584313725490196 1" />
      </material>
    </visual>
    <collision>
      <origin
        xyz="0 0 0"
        rpy="0 0 0" />
      <geometry>
        <mesh
          filename="file://$(find myco_description)/meshes/MyCo-3-0.59/myco_link1.STL" />
      </geometry>
    </collision>
  </link>
  <joint
    name="myco_joint1"
    type="revolute">
    <origin
      xyz="0 0 0.1925"
      rpy="0 0 0" />
    <parent
      link="myco_base" />
    <child
      link="myco_link1" />
    <axis
      xyz="0 0 1" />
    <limit
      lower="-6.283"
      upper="6.283"
      effort="200"
      velocity="1.57" />
  </joint>
  <link
    name="myco_link2">
    <inertial>
      <origin
        xyz="-1.23403972475124E-05 0.122745297432378 0.107454785665814"
        rpy="0 0 0" />
      <mass
        value="1.32916357022771" />
      <inertia
        ixx="0.0143234899021343"
        ixy="2.46462340307109E-06"
        ixz="-1.75693312623305E-07"
        iyy="0.000965876134991096"
        iyz="0.000630957725186578"
        izz="0.0145986007700288" />
    </inertial>
    <visual>
      <origin
        xyz="0 0 0"
        rpy="0 0 0" />
      <geometry>
        <mesh
          filename="file://$(find myco_description)/meshes/MyCo-3-0.59/myco_link2.STL" />
      </geometry>
      <material
        name="">
        <color
          rgba="0.792156862745098 0.819607843137255 0.933333333333333 1" />
      </material>
    </visual>
    <collision>
      <origin
        xyz="0 0 0"
        rpy="0 0 0" />
      <geometry>
        <mesh
          filename="file://$(find myco_description)/meshes/MyCo-3-0.59/myco_link2.STL" />
      </geometry>
    </collision>
  </link>
  <joint
    name="myco_joint2"
    type="revolute">
    <origin
      xyz="0 0 0"
      rpy="1.5708 0 0" />
    <parent
      link="myco_link1" />
    <child
      link="myco_link2" />
    <axis
      xyz="0 0 1" />
    <limit
      lower="-2.356"
      upper="2.356"
      effort="200"
      velocity="1.57" />
  </joint>
  <link
    name="myco_link3">
    <inertial>
      <origin
        xyz="0.0273503495467048 5.48033723722187E-06 -0.00487896906940542"
        rpy="0 0 0" />
      <mass
        value="1.35242975944115" />
      <inertia
        ixx="0.00178064753609302"
        ixy="-2.20907651848147E-07"
        ixz="-0.000626857689812886"
        iyy="0.00332334728865562"
        iyz="-5.56828856646333E-07"
        izz="0.00287611488669265" />
    </inertial>
    <visual>
      <origin
        xyz="0 0 0"
        rpy="0 0 0" />
      <geometry>
        <mesh
          filename="file://$(find myco_description)/meshes/MyCo-3-0.59/myco_link3.STL" />
      </geometry>
      <material
        name="">
        <color
          rgba="0.772549019607843 0.752941176470588 0.733333333333333 1" />
      </material>
    </visual>
    <collision>
      <origin
        xyz="0 0 0"
        rpy="0 0 0" />
      <geometry>
        <mesh
          filename="file://$(find myco_description)/meshes/MyCo-3-0.59/myco_link3.STL" />
      </geometry>
    </collision>
  </link>
  <joint
    name="myco_joint3"
    type="revolute">
    <origin
      xyz="0 0.266 0"
      rpy="3.1416 0 1.5708" />
    <parent
      link="myco_link2" />
    <child
      link="myco_link3" />
    <axis
      xyz="0 0 1" />
    <limit
      lower="-2.618"
      upper="2.618"
      effort="200"
      velocity="1.57" />
  </joint>
  <link
    name="myco_link4">
    <inertial>
      <origin
        xyz="9.09337261467621E-07 -0.0599929358061034 0.203743684852779"
        rpy="0 0 0" />
      <mass
        value="1.01622718378241" />
      <inertia
        ixx="0.00719645653258954"
        ixy="1.63948762478838E-08"
        ixz="7.94617347930607E-09"
        iyy="0.00589240676079192"
        iyz="0.00214741597243281"
        izz="0.00220714232180134" />
    </inertial>
    <visual>
      <origin
        xyz="0 0 0"
        rpy="0 0 0" />
      <geometry>
        <mesh
          filename="file://$(find myco_description)/meshes/MyCo-3-0.59/myco_link4.STL" />
      </geometry>
      <material
        name="">
        <color
          rgba="0.792156862745098 0.819607843137255 0.933333333333333 1" />
      </material>
    </visual>
    <collision>
      <origin
        xyz="0 0 0"
        rpy="0 0 0" />
      <geometry>
        <mesh
          filename="file://$(find myco_description)/meshes/MyCo-3-0.59/myco_link4.STL" />
      </geometry>
    </collision>
  </link>
  <joint
    name="myco_joint4"
    type="revolute">
    <origin
      xyz="0 0 0"
      rpy="1.5708 0 1.5708" />
    <parent
      link="myco_link3" />
    <child
      link="myco_link4" />
    <axis
      xyz="0 0 1" />
    <limit
      lower="-6.283"
      upper="6.283"
      effort="104"
      velocity="1.57" />
  </joint>
  <link
    name="myco_link5">
    <inertial>
      <origin
        xyz="-4.65990510061934E-07 -0.0225167615518929 -0.00429956563234533"
        rpy="0 0 0" />
      <mass
        value="0.990243418796126" />
      <inertia
        ixx="0.00193102719905894"
        ixy="3.96600153117993E-08"
        ixz="9.44649960529068E-08"
        iyy="0.00109724731750724"
        iyz="0.00037478584640254"
        izz="0.00160806944895717" />
    </inertial>
    <visual>
      <origin
        xyz="0 0 0"
        rpy="0 0 0" />
      <geometry>
        <mesh
          filename="file://$(find myco_description)/meshes/MyCo-3-0.59/myco_link5.STL" />
      </geometry>
      <material
        name="">
        <color
          rgba="0.792156862745098 0.819607843137255 0.933333333333333 1" />
      </material>
    </visual>
    <collision>
      <origin
        xyz="0 0 0"
        rpy="0 0 0" />
      <geometry>
        <mesh
          filename="file://$(find myco_description)/meshes/MyCo-3-0.59/myco_link5.STL" />
      </geometry>
    </collision>
  </link>
  <joint
    name="myco_joint5"
    type="revolute">
    <origin
      xyz="0 0 0.324"
      rpy="-1.5708 0 0" />
    <parent
      link="myco_link4" />
    <child
      link="myco_link5" />
    <axis
      xyz="0 0 1" />
    <limit
      lower="-2.565"
      upper="2.565"
      effort="34"
      velocity="1.57" />
  </joint>
  <link
    name="myco_link6">
    <inertial>
      <origin
        xyz="-6.05886244690852E-07 -0.000147343219411144 0.137754332176962"
        rpy="0 0 0" />
      <mass
        value="0.388090511103691" />
      <inertia
        ixx="0.000323304127961029"
        ixy="-1.16776769737677E-07"
        ixz="9.14999120612086E-08"
        iyy="0.000320919946003903"
        iyz="9.26097135186965E-07"
        izz="0.000361389016541944" />
    </inertial>
    <visual>
      <origin
        xyz="0 0 0"
        rpy="0 0 0" />
      <geometry>
        <mesh
          filename="file://$(find myco_description)/meshes/MyCo-3-0.59/myco_link6.STL" />
      </geometry>
      <material
        name="">
        <color
          rgba="0.792156862745098 0.819607843137255 0.933333333333333 1" />
      </material>
    </visual>
    <collision>
      <origin
        xyz="0 0 0"
        rpy="0 0 0" />
      <geometry>
        <mesh
          filename="file://$(find myco_description)/meshes/MyCo-3-0.59/myco_link6.STL" />
      </geometry>
    </collision>
  </link>
  <joint
    name="myco_joint6"
    type="revolute">
    <origin
      xyz="0 0 0"
      rpy="1.5708 0 0" />
    <parent
      link="myco_link5" />
    <child
      link="myco_link6" />
    <axis
      xyz="0 0 1" />
    <limit
      lower="-6.283"
      upper="6.283"
      effort="34"
      velocity="1.57" />
  </joint>
  <link
    name="myco_end_link">
  </link>
  <joint
    name="myco_end_joint"
    type="fixed">
    <origin
      xyz="0 0 0.175"
      rpy="0 0 0" />
    <parent
      link="myco_link6" />
    <child
      link="myco_end_link" />
    <axis
      xyz="0 0 0" />
  </joint>
  
</robot>